package examples;

import com.tsys.utils.Try;

public class RecoveryExamples {
    public static void main(String[] args) {
        Try.with(() -> {throw new RuntimeException(); });
        final Try<Integer> answer = Try.with(() -> 2 / 0)
                .recover(t -> 2)
                .map(x -> {
                    throw new RuntimeException();
                })
                .recover(t -> 4);
        System.out.println("answer = " + answer);

        final Try<Integer> answer2 = Try.with(() -> 12 / 0)
                .recover(t -> 2)
                .map(x -> x * 4)
                .recover(t -> 4);
        System.out.println("answer2 = " + answer2);

        final Try<Double> answer3 = Try.with(() -> 2)
                .recover(t -> 2)
                .map(x -> {
                    throw new RuntimeException("fatal");
                })
                .recoverWith(t -> Try.with(() -> 10d));
        System.out.println("answer3 = " + answer3);

        //Chain of Responsibility using recover/recoverWith
        final Try<Double> answer4 =
//                Try.with(() -> 2 / 0) //Success(10.0)
                Try.with(() -> Integer.valueOf(null)) //Success(4)
                .recover(t -> {
                    if (t.getClass() == NumberFormatException.class) {
                        return 2;
                    }
                    throw new RuntimeException(t);
                })
                .map(x -> x * 2)
                .recoverWith(t -> Try.with(() -> 10d));
        System.out.println("answer4 = " + answer4);

    }
}
